<?xml version='1.0'?>
<sdf version='1.9'>
  <world name='puzzlebot_world'>
    <physics name='1ms' type='ignored'>
      <max_step_size>0.001</max_step_size>
      <real_time_factor>1</real_time_factor>
      <real_time_update_rate>1000</real_time_update_rate>
    </physics>
    <plugin name='gz::sim::systems::Physics' filename='ignition-gazebo-physics-system'/>
    <plugin name='gz::sim::systems::UserCommands' filename='ignition-gazebo-user-commands-system'/>
    <plugin name='gz::sim::systems::SceneBroadcaster' filename='ignition-gazebo-scene-broadcaster-system'/>
    <gravity>0 0 -9.8</gravity>
    <magnetic_field>6e-06 2.3e-05 -4.2e-05</magnetic_field>
    <atmosphere type='adiabatic'/>
    <scene>
      <ambient>0.4 0.4 0.4 1</ambient>
      <background>0.7 0.7 0.7 1</background>
      <shadows>true</shadows>
    </scene>
    
    <!-- Ground plane -->
    <model name='ground_plane'>
      <static>true</static>
      <link name='link'>
        <collision name='collision'>
          <geometry>
            <plane>
              <normal>0 0 1</normal>
              <size>100 100</size>
            </plane>
          </geometry>
          <surface>
            <friction>
              <ode/>
            </friction>
            <bounce/>
            <contact/>
          </surface>
        </collision>
        <visual name='visual'>
          <geometry>
            <plane>
              <normal>0 0 1</normal>
              <size>100 100</size>
            </plane>
          </geometry>
          <material>
            <ambient>0.8 0.8 0.8 1</ambient>
            <diffuse>0.8 0.8 0.8 1</diffuse>
            <specular>0.8 0.8 0.8 1</specular>
          </material>
        </visual>
        <pose>0 0 0 0 -0 0</pose>
        <inertial>
          <pose>0 0 0 0 -0 0</pose>
          <mass>1</mass>
          <inertia>
            <ixx>1</ixx>
            <ixy>0</ixy>
            <ixz>0</ixz>
            <iyy>1</iyy>
            <iyz>0</iyz>
            <izz>1</izz>
          </inertia>
        </inertial>
        <enable_wind>false</enable_wind>
      </link>
      <pose>0 0 0 0 -0 0</pose>
      <self_collide>false</self_collide>
    </model>
    
    <!-- PuzzleBot model with diff_drive functionality -->
    <model name='vehicle_blue' canonical_link='chassis'>
      <!-- Chassis -->
      <link name='chassis'>
        <pose relative_to='__model__'>0 0 0.05 0 0 0</pose>
        
        <inertial>
          <mass>0.8</mass>
          <pose>-0.05 0 0 0 0 0</pose>
          <inertia>
            <ixx>0.004</ixx>
            <iyy>0.004</iyy>
            <izz>0.004</izz>
            <ixy>0</ixy>
            <ixz>0</ixz>
            <iyz>0</iyz>
          </inertia>
        </inertial>
        
        <visual name='visual'>
          <geometry>
            <mesh>
              <uri>puzzlebot/meshes/chassis1.dae</uri>
            </mesh>
          </geometry>
        </visual>
        
        <collision name='collision'>
          <pose>-0.055 0 0 0 0 0</pose>
          <geometry>
            <box>
              <size>0.2 0.16 0.046</size>
            </box>
          </geometry>
        </collision>
      </link>

      <!-- Right wheel -->
      <link name='right_wheel'>
        <pose relative_to="chassis">0.0 -0.095 0 0 0 3.1415</pose>
        
        <inertial>
          <mass>0.05</mass>
          <inertia>
            <ixx>0.002</ixx>
            <iyy>0.002</iyy>
            <izz>0.002</izz>
            <ixy>0</ixy>
            <ixz>0</ixz>
            <iyz>0</iyz>
          </inertia>
        </inertial>
        
        <visual name='visual'>
          <geometry>
            <mesh>
              <uri>puzzlebot/meshes/wheel.dae</uri>
            </mesh>
          </geometry>
        </visual>
        
        <collision name='collision'>
          <pose>0 -0.0025 0 1.5707 0 0</pose>
          <geometry>
            <cylinder>
              <radius>0.05</radius>
              <length>0.005</length>
            </cylinder>
          </geometry>
          <surface>
            <friction>
              <ode>
                <mu>1.0</mu>
                <mu2>1.0</mu2>
              </ode>
            </friction>
          </surface>
        </collision>
      </link>

      <!-- Left wheel -->
      <link name='left_wheel'>
        <pose relative_to="chassis">0.0 0.095 0 0 0 0</pose>
        
        <inertial>
          <mass>0.05</mass>
          <inertia>
            <ixx>0.002</ixx>
            <iyy>0.002</iyy>
            <izz>0.002</izz>
            <ixy>0</ixy>
            <ixz>0</ixz>
            <iyz>0</iyz>
          </inertia>
        </inertial>
        
        <visual name='visual'>
          <geometry>
            <mesh>
              <uri>puzzlebot/meshes/wheel.dae</uri>
            </mesh>
          </geometry>
        </visual>
        
        <collision name='collision'>
          <pose>0 -0.0025 0 1.5707 0 0</pose>
          <geometry>
            <cylinder>
              <radius>0.05</radius>
              <length>0.005</length>
            </cylinder>
          </geometry>
          <surface>
            <friction>
              <ode>
                <mu>1.0</mu>
                <mu2>1.0</mu2>
              </ode>
            </friction>
          </surface>
        </collision>
      </link>

      <!-- Caster frame -->
      <frame name="caster_frame" attached_to='chassis'>
        <pose>-0.145 0 -0.044 0 0 0</pose>
      </frame>

      <!-- Caster wheel -->
      <link name='caster'>
        <pose relative_to='caster_frame'/>
        
        <inertial>
          <mass>0.01</mass>
          <inertia>
            <ixx>0.0000025</ixx>
            <iyy>0.0000025</iyy>
            <izz>0.0000025</izz>
            <ixy>0</ixy>
            <ixz>0</ixz>
            <iyz>0</iyz>
          </inertia>
        </inertial>
        
        <visual name='visual'>
          <geometry>
            <sphere>
              <radius>0.006</radius>
            </sphere>
          </geometry>
          <material>
            <ambient>0.0 1 0.0 1</ambient>
            <diffuse>0.0 1 0.0 1</diffuse>
            <specular>0.0 1 0.0 1</specular>
          </material>
        </visual>
        
        <collision name='collision'>
          <geometry>
            <sphere>
              <radius>0.006</radius>
            </sphere>
          </geometry>
        </collision>
      </link>

      <!-- Left wheel joint -->
      <joint name='left_wheel_joint' type='revolute'>
        <pose relative_to='left_wheel'/>
        <parent>chassis</parent>
        <child>left_wheel</child>
        <axis>
          <xyz expressed_in='__model__'>0 1 0</xyz>
          <limit>
            <lower>-1.79769e+308</lower>
            <upper>1.79769e+308</upper>
            <effort>1</effort>
            <velocity>inf</velocity>
          </limit>
          <dynamics>
            <friction>0.1</friction>
            <damping>0</damping>
          </dynamics>
        </axis>
      </joint>

      <!-- Right wheel joint -->
      <joint name='right_wheel_joint' type='revolute'>
        <pose relative_to='right_wheel'/>
        <parent>chassis</parent>
        <child>right_wheel</child>
        <axis>
          <xyz expressed_in='__model__'>0 1 0</xyz>
          <limit>
            <lower>-1.79769e+308</lower>
            <upper>1.79769e+308</upper>
            <effort>1</effort>
            <velocity>inf</velocity>
          </limit>
          <dynamics>
            <friction>0.1</friction>
            <damping>0</damping>
          </dynamics>
        </axis>
      </joint>

      <!-- Caster wheel joint -->
      <joint name='caster_wheel' type='ball'>
        <parent>chassis</parent>
        <child>caster</child>
      </joint>
      
      <!-- Diff Drive plugin from working model -->
      <plugin name='gz::sim::systems::DiffDrive' filename='ignition-gazebo-diff-drive-system'>
        <left_joint>left_wheel_joint</left_joint>
        <right_joint>right_wheel_joint</right_joint>
        <wheel_separation>0.19</wheel_separation> <!-- Distance between the wheels (adjusted for PuzzleBot) -->
        <wheel_radius>0.05</wheel_radius> <!-- Wheel radius from PuzzleBot model -->
        <odom_publish_frequency>1</odom_publish_frequency>
        <max_linear_acceleration>1</max_linear_acceleration>
        <min_linear_acceleration>-1</min_linear_acceleration>
        <max_angular_acceleration>2</max_angular_acceleration>
        <min_angular_acceleration>-2</min_angular_acceleration>
        <max_linear_velocity>0.5</max_linear_velocity>
        <min_linear_velocity>-0.5</min_linear_velocity>
        <max_angular_velocity>1</max_angular_velocity>
        <min_angular_velocity>-1</min_angular_velocity>
      </plugin>
      
      <pose>0 0 0.05 0 0 0</pose>
      <static>false</static>
      <self_collide>false</self_collide>
    </model>
    
    <!-- Light source -->
    <light name='sun' type='directional'>
      <pose>0 0 10 0 -0 0</pose>
      <cast_shadows>true</cast_shadows>
      <intensity>1</intensity>
      <direction>-0.5 0.1 -0.9</direction>
      <diffuse>1 1 1 1</diffuse>
      <specular>0.5 0.5 0.5 1</specular>
      <attenuation>
        <range>1000</range>
        <linear>0.01</linear>
        <constant>0.90000000000000002</constant>
        <quadratic>0.001</quadratic>
      </attenuation>
      <spot>
        <inner_angle>0</inner_angle>
        <outer_angle>0</outer_angle>
        <falloff>0</falloff>
      </spot>
    </light>
  </world>
</sdf>
